<?xml version="1.0" ?>
<!-- =================================================================================== -->
<!-- |    This document was autogenerated by xacro from /home/lf4943s/gazebo_train/install/gazebo_train_description/share/gazebo_train_description/urdf/gazebo_train.urdf.xacro | -->
<!-- |    EDITING THIS FILE BY HAND IS NOT RECOMMENDED                                 | -->
<!-- =================================================================================== -->
<robot name="gazebo_train">
    <!-- Init colour -->
    <material name="black">
        <color rgba="0.0 0.0 0.0 1.0"/>
    </material>
    <material name="dark">
        <color rgba="0.3 0.3 0.3 1.0"/>
    </material>
    <material name="light_black">
        <color rgba="0.4 0.4 0.4 1.0"/>
    </material>
    <material name="blue">
        <color rgba="0.0 0.0 0.8 1.0"/>
    </material>
    <material name="green">
        <color rgba="0.0 0.8 0.0 1.0"/>
    </material>
    <material name="grey">
        <color rgba="0.5 0.5 0.5 1.0"/>
    </material>
    <material name="orange">
        <color rgba="1.0 0.4235294117647059 0.0392156862745098 1.0"/>
    </material>
    <material name="brown">
        <color rgba="0.8705882352941177 0.8117647058823529 0.7647058823529411 1.0"/>
    </material>
    <material name="silver">
        <color rgba="0.7529411764705882 0.7529411764705882 0.7529411764705882 1.0"/>
    </material>
    <material name="red">
        <color rgba="0.8 0.0 0.0 1.0"/>
    </material>
    <material name="white">
        <color rgba="1.0 1.0 1.0 1.0"/>
    </material>
    <!-- Base -->
    <link name="base_footprint"/>
    <joint name="base_joint" type="fixed">
        <parent link="base_footprint"/>
        <child link="base_link"/>
        <origin rpy="0 0 0" xyz="0 0 -0.030"/>
    </joint>
    <link name="base_link">
        <visual>
            <origin rpy="0 0.01 0" xyz="-0.235 -0.278 0.285"/>
            <geometry>
                <mesh filename="package://gazebo_train_description/meshes/waffle_custom_base.stl" scale="0.001 0.001 0.001"/>
                <!-- make sure that the path points correctly to the mesh file -->
            </geometry>
            <material name="dark"/>
        </visual>
        <collision>
            <origin rpy="0 0.01 0" xyz="-0.10 0 0.07"/>
            <geometry>
                <box size="0.27 0.11 0.27"/>
            </geometry>
        </collision>
        <inertial>
            <origin rpy="0 0.01 0" xyz="-0.10 0 0.07"/>
            <mass value="1"/>
            <inertia ixx="0.0270833333" ixy="0.0" ixz="0.0" iyy="0.01215" iyz="0.0" izz="0.0270833333"/>
        </inertial>
    </link>
    <link name="wheel_left_link">
        <visual>
            <origin rpy="1.5707963267948966 0 0" xyz="0 0 0"/>
            <geometry>
                <mesh filename="package://gazebo_train_description/meshes/left_tire.stl" scale="0.001 0.001 0.001"/>
            </geometry>
            <material name="orange"/>
        </visual>
        <inertial>
            <origin xyz="0 0 0"/>
            <mass value="0.01"/>
            <inertia ixx="0.0000029925" ixy="0.0" ixz="0.0" iyy="0.0000029925" iyz="0.0" izz="0.000005445"/>
        </inertial>
        <collision>
            <origin rpy="0 0 0" xyz="0 0 0"/>
            <geometry>
                <cylinder length="0.1" radius="0.1"/>
            </geometry>
        </collision>
    </link>
    <joint name="wheel_left_joint" type="continuous">
        <parent link="base_link"/>
        <child link="wheel_left_link"/>
        <origin rpy="-1.5707963267948966 0 0" xyz="-0.455  -0.678 0.1350"/>
        <axis xyz="0 0 1"/>
    </joint>
    <link name="wheel_right_link">
        <visual>
            <origin rpy="1.5707963267948966 0 0" xyz="0 0 0"/>
            <geometry>
                <mesh filename="package://gazebo_train_description/meshes/right_tire.stl" scale="0.001 0.001 0.001"/>
            </geometry>
            <material name="orange"/>
        </visual>
        <inertial>
            <origin xyz="0 0 0"/>
            <mass value="0.01"/>
            <inertia ixx="0.0000029925" ixy="0.0" ixz="0.0" iyy="0.0000029925" iyz="0.0" izz="0.000005445"/>
        </inertial>
        <collision>
            <origin rpy="0 0 0" xyz="0 0 0"/>
            <geometry>
                <cylinder length="0.1" radius="0.1"/>
            </geometry>
        </collision>
    </link>
    <joint name="wheel_right_joint" type="continuous">
        <parent link="base_link"/>
        <child link="wheel_right_link"/>
        <origin rpy="-1.5707963267948966 0 0" xyz="-0.455  0.123 0.1350"/>
        <axis xyz="0 0 1"/>
    </joint>
    <link name="wheel_right2_link">
        <visual>
            <origin rpy="1.5707963267948966 0 0" xyz="0 0 0"/>
            <geometry>
                <mesh filename="package://gazebo_train_description/meshes/right_tire.stl" scale="0.001 0.001 0.001"/>
            </geometry>
            <material name="orange"/>
        </visual>
        <inertial>
            <origin xyz="0 0 0"/>
            <mass value="0.01"/>
            <inertia ixx="0.0000029925" ixy="0.0" ixz="0.0" iyy="0.0000029925" iyz="0.0" izz="0.000005445"/>
        </inertial>
        <collision>
            <origin rpy="0 0 0" xyz="0 0 0"/>
            <geometry>
                <cylinder length="0.1" radius="0.1"/>
            </geometry>
        </collision>
    </link>
    <joint name="wheel_right2_joint" type="continuous">
        <parent link="base_link"/>
        <child link="wheel_right2_link"/>
        <origin rpy="-1.5707963267948966 0 -3.141592653589793 " xyz="-0.015 0.123 0.1350"/>
        <axis xyz="0 0 1"/>
    </joint>
    <link name="wheel_left2_link">
        <visual>
            <origin rpy="1.5707963267948966 0 0" xyz="0 0 0"/>
            <geometry>
                <mesh filename="package://gazebo_train_description/meshes/left_tire.stl" scale="0.001 0.001 0.001"/>
            </geometry>
            <material name="orange"/>
        </visual>
        <inertial>
            <origin xyz="0 0 0"/>
            <mass value="0.01"/>
            <inertia ixx="0.0000029925" ixy="0.0" ixz="0.0" iyy="0.0000029925" iyz="0.0" izz="0.000005445"/>
        </inertial>
        <collision>
            <origin rpy="0 0 0" xyz="0 0 0"/>
            <geometry>
                <cylinder length="0.1" radius="0.1"/>
            </geometry>
        </collision>
    </link>
    <joint name="wheel_left2_joint" type="continuous">
        <parent link="base_link"/>
        <child link="wheel_left2_link"/>
        <origin rpy="-1.5707963267948966 0 -3.141592653589793 " xyz="-0.015 -0.678 0.1350"/>
        <axis xyz="0 0 1"/>
    </joint>
    <link name="camera_link">
        <visual>
            <origin rpy="1.5707963267948966 0 1.5707963267948966" xyz="0 0 0"/>
            <geometry>
                <mesh filename="package://tb3_description/meshes/webcam.stl" scale="0.0001 0.0001 0.0001"/>
            </geometry>
            <material name="red"/>
        </visual>
        <inertial>
            <origin xyz="0 0 0"/>
            <mass value="0.001"/>
            <inertia ixx="0.001" ixy="0.0" ixz="0.0" iyy="0.001" iyz="0.0" izz="0.001"/>
        </inertial>
    </link>
    <joint name="camera_base_joint" type="fixed">
        <parent link="base_link"/>
        <child link="camera_link"/>
        <origin rpy="0 0 1.5" xyz="-0.15 -0.02 0.785"/>
    </joint>
    <link name="camera_lens_link"/>
    <joint name="camera_lens_joint" type="fixed">
        <parent link="camera_link"/>
        <child link="camera_lens_link"/>
        <origin rpy="-1.571 0 -1.571" xyz=" 0.25 0.02 0.09"/>
    </joint>
    <link name="imu_link"/>
    <joint name="imu_joint" type="fixed">
        <parent link="base_link"/>
        <child link="imu_link"/>
        <origin rpy="0 0 0" xyz="-0.25 -0.250 0.468"/>
    </joint>
    <link name="laser_link">
        <visual>
            <origin rpy="1.5707963267948966 0 0" xyz="-0.035 0.036 0.020"/>
            <geometry>
                <mesh filename="package://tb3_description/meshes/RPLIDAR.stl" scale="0.001 0.001 0.001"/>
            </geometry>
            <material name="red"/>
        </visual>
        <inertial>
            <origin xyz="0 0 0"/>
            <mass value="0.2"/>
            <inertia ixx="0.001" ixy="0.0" ixz="0.0" iyy="0.001" iyz="0.0" izz="0.001"/>
        </inertial>
        <collision>
            <origin rpy="1.5707963267948966 0 0" xyz="0 0 0"/>
            <geometry>
                <box size="0.1 0.056 0.420"/>
            </geometry>
        </collision>
    </link>
    <joint name="laser_joint" type="fixed">
        <parent link="base_link"/>
        <child link="laser_link"/>
        <origin rpy="0 0 0" xyz="-0.02 0 0.80"/>
    </joint>
</robot>
