<?xml version="1.0" ?>
<!-- =================================================================================== -->
<!-- |    This document was autogenerated by xacro from /home/lf4943s/gazebo_train/install/gazebo_train_description/share/gazebo_train_description/urdf/gazebo_train.urdf.xacro | -->
<!-- |    EDITING THIS FILE BY HAND IS NOT RECOMMENDED                                 | -->
<!-- =================================================================================== -->
<robot name="gazebo_train">
    <!-- Init colour -->
    <material name="black">
        <color rgba="0.0 0.0 0.0 1.0"/>
    </material>
    <material name="dark">
        <color rgba="0.3 0.3 0.3 1.0"/>
    </material>
    <material name="light_black">
        <color rgba="0.4 0.4 0.4 1.0"/>
    </material>
    <material name="blue">
        <color rgba="0.0 0.0 0.8 1.0"/>
    </material>
    <material name="green">
        <color rgba="0.0 0.8 0.0 1.0"/>
    </material>
    <material name="grey">
        <color rgba="0.5 0.5 0.5 1.0"/>
    </material>
    <material name="orange">
        <color rgba="1.0 0.4235294117647059 0.0392156862745098 1.0"/>
    </material>
    <material name="brown">
        <color rgba="0.8705882352941177 0.8117647058823529 0.7647058823529411 1.0"/>
    </material>
    <material name="silver">
        <color rgba="0.7529411764705882 0.7529411764705882 0.7529411764705882 1.0"/>
    </material>
    <material name="red">
        <color rgba="0.8 0.0 0.0 1.0"/>
    </material>
    <material name="white">
        <color rgba="1.0 1.0 1.0 1.0"/>
    </material>
    
    <link name="base_footprint"/>
    <joint name="base_joint" type="fixed">
        <parent link="base_footprint"/>
        <child link="base_link"/>
        <origin rpy="0 0 3.141592653589793" xyz="0 0 0.3"/>  
    </joint>
    <link name="base_link">
        <visual>
            <origin rpy="0 0 3.141592653589793" xyz="0 0 0.25"/>
            <geometry>
                <mesh filename="package://gazebo_train_description/meshes/emma_base.stl" scale="0.001 0.001 0.001"/>
            </geometry>
            <material name="dark"/>
        </visual>
        <collision>
            <origin rpy="0 0 3.141592653589793" xyz="-0.10 0 0.07"/>
            <geometry>
                <mesh filename="package://gazebo_train_description/meshes/emma_base.stl" scale="0.001 0.001 0.001"/>
            </geometry>
        </collision>
        <inertial>
            <origin rpy="0 0 3.141592653589793" xyz="-0.10 0 0.07"/>
            <mass value="1"/>
            <inertia ixx="0.6" ixy="0.0" ixz="0.0" iyy="0.2" iyz="0.0" izz="0.6"/>
        </inertial>
    </link>

    <link name="laser_link">  
      <sensor name="hls_lfcd_lds" type="ray">
        <always_on>true</always_on>
        <visualize>false</visualize>
        <pose>0 0 0 0 0 0</pose>
        <update_rate>10</update_rate>
        <ray>
          <scan>
            <horizontal>
              <samples>1024</samples>
              <resolution>1.000000</resolution>
              <min_angle>0.000000</min_angle>
              <max_angle>6.280000</max_angle>
            </horizontal>
          </scan>
          <range>
            <min>0.5</min>
            <max>120</max>
            <resolution>0.0010000</resolution>
          </range>
          <noise>
            <type>gaussian</type>
            <mean>0.0</mean>
            <stddev>0.01</stddev>
          </noise>
        </ray>
        <plugin name="train_laserscan" filename="libgazebo_ros_ray_sensor.so">
          <ros>
            <remapping>~/out:=scan</remapping>
          </ros>
          <output_type>sensor_msgs/LaserScan</output_type>
          <frame_name>base_footprint</frame_name>
        </plugin>
      </sensor>
    </link>
    
    <joint name="lidar_joint" type="fixed">
        <parent link="base_link"/>
        <child link="laser_link"/>
        <origin rpy="0 0 3.14159" xyz="0 0.9 0.88"/>
        <axis xyz="0 0 1"/>
    </joint>

    <link name="camera_link">
      <visual>
        <origin xyz="0 0 0" rpy="0 0 0"/>
        <geometry>
          <mesh filename="package://gazebo_train_description/meshes/webcam.stl" scale="0.0006 0.0006 0.0006"/>
        </geometry>
        <material name="black"/>
      </visual>
      <inertial>
        <origin xyz="0 0 0 " />
        <mass value="0.001" />
        <inertia ixx="0.001" ixy="0.0" ixz="0.0" iyy="0.001" iyz="0.0" izz="0.001" />
      </inertial>
    </link>
    <joint name="camera_base_joint" type="fixed">
      <parent link="base_link"/>
      <child link="camera_link"/>
      <origin xyz="0 1.0 0.874" rpy="0 0 0"/>
    </joint>
    <link name="camera_lens_link"/>
    <joint name="camera_lens_joint" type="fixed">
      <parent link="camera_link"/>
      <child link="camera_lens_link"/>
      <origin xyz="0.1 0 0" rpy="-1.57 0 0 "/>
    </joint>

    <link name="imu_link"/>
    <joint name="imu_joint" type="fixed">
        <parent link="base_link"/>
        <child link="imu_link"/>
        <origin xyz="0 0 0" rpy="0 0 0"/>
    </joint>

    <!-- Left Wheel -->
    <link name="wheel_left_link">
        <visual>
            <origin rpy="1.5707963267948966 0 0" xyz="0 0 0"/>
            <geometry>
                <mesh filename="package://gazebo_train_description/meshes/rad.stl" scale="0.001 0.001 0.001"/>
            </geometry>
            <material name="orange"/>
        </visual>
        <inertial>
            <origin xyz="0 0 0"/>
            <mass value="0.01"/>
            <inertia ixx="0.0000029925" ixy="0.0" ixz="0.0" iyy="0.0000029925" iyz="0.0" izz="0.000005445"/>
        </inertial>
        <collision>
            <origin rpy="-1.5708 0 0" xyz="0 0 0"/>
            <geometry>
                <mesh filename="package://gazebo_train_description/meshes/rad.stl" scale="0.001 0.001 0.001"/>
            </geometry>
        </collision>
    </link>
    <joint name="wheel_left_joint" type="continuous">
        <parent link="base_link"/>
        <child link="wheel_left_link"/>
        <origin rpy="-1.5707963267948966 0 0" xyz="-0.13 -0.405 0"/>
        <axis xyz="1 0 0"/>
    </joint>

    <!-- Left Wheel 2 -->
    <link name="wheel_left2_link">
        <visual>
            <origin rpy="1.5707963267948966 0 0" xyz="0 0 0"/>
            <geometry>
                <mesh filename="package://gazebo_train_description/meshes/rad.stl" scale="0.001 0.001 0.001"/>
            </geometry>
            <material name="orange"/>
        </visual>
        <inertial>
            <origin xyz="0 0 0"/>
            <mass value="0.01"/>
            <inertia ixx="0.0000029925" ixy="0.0" ixz="0.0" iyy="0.0000029925" iyz="0.0" izz="0.000005445"/>
        </inertial>
        <collision>
            <origin rpy="-1.5708 0 0" xyz="0 0 0"/>
            <geometry>
                <mesh filename="package://gazebo_train_description/meshes/rad.stl" scale="0.001 0.001 0.001"/>
            </geometry>
        </collision>
    </link>
    <joint name="wheel_left2_joint" type="continuous">
        <parent link="base_link"/>
        <child link="wheel_left2_link"/>
        <origin rpy="-1.5707963267948966 0 0" xyz="-0.13 0.405 0"/>
        <axis xyz="1 0 0"/>
    </joint>


    <!-- Left Wheel 3 -->
    <link name="wheel_left3_link">
        <visual>
            <origin rpy="1.5707963267948966 0 0" xyz="0 0 0"/>
            <geometry>
                <mesh filename="package://gazebo_train_description/meshes/rad.stl" scale="0.001 0.001 0.001"/>
            </geometry>
            <material name="orange"/>
        </visual>
        <inertial>
            <origin xyz="0 0 0"/>
            <mass value="0.01"/>
            <inertia ixx="0.0000029925" ixy="0.0" ixz="0.0" iyy="0.0000029925" iyz="0.0" izz="0.000005445"/>
        </inertial>
        <collision>
            <origin rpy="-1.5708 0 0" xyz="0 0 0"/>
            <geometry>
                <mesh filename="package://gazebo_train_description/meshes/rad.stl" scale="0.001 0.001 0.001"/>
            </geometry>
        </collision>
    </link>
    <joint name="wheel_left3_joint" type="continuous">
        <parent link="base_link"/>
        <child link="wheel_left3_link"/>
        <origin rpy="-1.5707963267948966 0 0" xyz="-0.13 -0.8 0"/>
        <axis xyz="1 0 0"/>
    </joint>

    <!-- Left Wheel 4 -->
    <link name="wheel_left4_link">
        <visual>
            <origin rpy="1.5707963267948966 0 0" xyz="0 0 0"/>
            <geometry>
                <mesh filename="package://gazebo_train_description/meshes/rad.stl" scale="0.001 0.001 0.001"/>
            </geometry>
            <material name="orange"/>
        </visual>
        <inertial>
            <origin xyz="0 0 0"/>
            <mass value="0.01"/>
            <inertia ixx="0.0000029925" ixy="0.0" ixz="0.0" iyy="0.0000029925" iyz="0.0" izz="0.000005445"/>
        </inertial>
        <collision>
            <origin rpy="-1.5708 0 0" xyz="0 0 0"/>
            <geometry>
                <mesh filename="package://gazebo_train_description/meshes/rad.stl" scale="0.001 0.001 0.001"/>
            </geometry>
        </collision>
    </link>
    <joint name="wheel_left4_joint" type="continuous">
        <parent link="base_link"/>
        <child link="wheel_left4_link"/>
        <origin rpy="-1.5707963267948966 0 0" xyz="-0.13 0.79 0"/>
        <axis xyz="1 0 0"/>
    </joint>

    <!-- Right Wheel -->
    <link name="wheel_right_link">
        <visual>
            <origin rpy="1.5707963267948966 0 0" xyz="0 0 0"/>
            <geometry>
                <mesh filename="package://gazebo_train_description/meshes/rad.stl" scale="0.001 0.001 0.001"/>
            </geometry>
            <material name="orange"/>
        </visual>
        <inertial>
            <origin xyz="0 0 0"/>
            <mass value="0.01"/>
            <inertia ixx="0.0000029925" ixy="0.0" ixz="0.0" iyy="0.0000029925" iyz="0.0" izz="0.000005445"/>
        </inertial>
        <collision>
            <origin rpy="-1.5708 0 0" xyz="0 0 0"/>
            <geometry>
                <mesh filename="package://gazebo_train_description/meshes/rad.stl" scale="0.001 0.001 0.001"/>
            </geometry>
        </collision>
    </link>
    <joint name="wheel_right_joint" type="continuous">
        <parent link="base_link"/>
        <child link="wheel_right_link"/>
        <origin rpy="-1.5707963267948966 0 0" xyz="0.13 -0.405 0"/>
        <axis xyz="-1 0 0"/>
    </joint>


    <!-- Right Wheel 2 -->
    <link name="wheel_right2_link">
        <visual>
            <origin rpy="1.5707963267948966 0 0" xyz=" 0 0 0"/>
            <geometry>
                <mesh filename="package://gazebo_train_description/meshes/rad.stl" scale="0.001 0.001 0.001"/>
            </geometry>
            <material name="orange"/>
        </visual>
        <inertial>
            <origin xyz="0 0 0"/>
            <mass value="0.01"/>
            <inertia ixx="0.0000029925" ixy="0.0" ixz="0.0" iyy="0.0000029925" iyz="0.0" izz="0.000005445"/>
        </inertial>
        <collision>
            <origin rpy="-1.5708 0 0" xyz="0 0 0"/>
            <geometry>
                <mesh filename="package://gazebo_train_description/meshes/rad.stl" scale="0.001 0.001 0.001"/>
            </geometry>
        </collision>
    </link>
    <joint name="wheel_right2_joint" type="continuous">
        <parent link="base_link"/>
        <child link="wheel_right2_link"/>
        <origin rpy="-1.5707963267948966 0 0" xyz="0.13 0.402 0"/>
        <axis xyz="-1 0 0"/>
    </joint>

    <!-- Right Wheel 3 -->
    <link name="wheel_right3_link">
        <visual>
            <origin rpy="1.5707963267948966 0 0" xyz="0 0 0"/>
            <geometry>
                <mesh filename="package://gazebo_train_description/meshes/rad.stl" scale="0.001 0.001 0.001"/>
            </geometry>
            <material name="orange"/>
        </visual>
        <inertial>
            <origin xyz="0 0 0"/>
            <mass value="0.01"/>
            <inertia ixx="0.0000029925" ixy="0.0" ixz="0.0" iyy="0.0000029925" iyz="0.0" izz="0.000005445"/>
        </inertial>
        <collision>
            <origin rpy="-1.5708 0 0" xyz="0 0 0"/>
            <geometry>
                <mesh filename="package://gazebo_train_description/meshes/rad.stl" scale="0.001 0.001 0.001"/>
            </geometry>
        </collision>
    </link>
    <joint name="wheel_right3_joint" type="continuous">
        <parent link="base_link"/>
        <child link="wheel_right3_link"/>
        <origin rpy="-1.5707963267948966 0 0" xyz="0.13 -0.8 0"/>
        <axis xyz="-1 0 0"/>
    </joint>

    <!-- Right Wheel 4 -->
    <link name="wheel_right4_link">
        <visual>
            <origin rpy="1.5707963267948966 0 0" xyz="0 0 0"/>
            <geometry>
                <mesh filename="package://gazebo_train_description/meshes/rad.stl" scale="0.001 0.001 0.001"/>
            </geometry>
            <material name="orange"/>
        </visual>
        <inertial>
            <origin xyz="0 0 0"/>
            <mass value="0.01"/>
            <inertia ixx="0.0000029925" ixy="0.0" ixz="0.0" iyy="0.0000029925" iyz="0.0" izz="0.000005445"/>
        </inertial>
        <collision>
            <origin rpy="-1.5708 0 0" xyz="0 0 0"/>
            <geometry>
                <mesh filename="package://gazebo_train_description/meshes/rad.stl" scale="0.001 0.001 0.001"/>
            </geometry>
        </collision>
    </link>
    <joint name="wheel_right4_joint" type="continuous">
        <parent link="base_link"/>
        <child link="wheel_right4_link"/>
        <origin rpy="-1.5707963267948966 0 0" xyz="0.13 0.79 0"/>
        <axis xyz="-1 0 0"/>
    </joint>

</robot>