<?xml version="1.0"?>
<robot xmlns:xacro="http://ros.org/wiki/xacro" name="gazebo_train_wheel">
    <xacro:macro name="gazebo_train_wheel" params="alignment *origin">
        <link name="wheel_${alignment}_link">
            <visual>
                <origin xyz="1.5708 0 0" rpy="${M_PI*0.5} 0 0"/>
                <geometry>
                    <mesh filename="package://gazebo_train_description/meshes/${alignment}_tire.stl" scale="0.001 0.001 0.001"/>
                </geometry>
                <material name="orange"/>
            </visual>
            <inertial>
                <origin xyz="0 0 0" />
                <mass value="0.01" />
                <inertia ixx="0.0000029925" ixy="0.0" ixz="0.0" iyy="0.0000029925" iyz="0.0" izz="0.000005445" />
            </inertial>
            <collision>
                <origin rpy="-1.5708 0 0" xyz="0 0 0"/>
                <geometry>
                    <mesh filename="package://gazebo_train_description/meshes/${alignment}_tire.stl" scale="0.001 0.001 0.001"/>
                </geometry>
            </collision>
        </link>
        <joint name="wheel_${alignment}_joint" type="continuous">
            <parent link="base_link"/>
            <child link="wheel_${alignment}_link"/>
            <xacro:insert_block name="origin"/>
        </joint>
    </xacro:macro>
</robot>
